### DOM事件和event loop
```
/* 异步 */
console.log('Hi')

setTimeout(function cb1() {
  console.log('cb1') // cb1 即 callback
}, 5000)

console.log('Bye')

/* DOM事件 */
<button id='btn1'>提交</button>
<script>
  console.log('Hi')
  
  $('btn1').click(function(e) {
    console.log('button clicked')
  })
  
  console.log('Bye')
</script>
```
注意： 只要该浏览器页面不关闭， 5s后 cb1才能被执行。 这个DOM事件，是只有点击了这个事件按钮，才会执行该响应的功能。
其实DOM事件和异步二者本质都是回调，区别是触发的时机是不一样的。为了让我们更清晰的理解DOM事件与event loop的关系，下面
我给了一张图

<img src='https://github.com/Bruce-shuai/Books/blob/main/JS基础/异步/photos/Event%20loop%20-%2012.png' height='200px' />

执行到click事件的时候，回调会放在Web APIs里。 什么时候点击了button按钮，什么时候这个回调就会放在callback queue里，
其他步骤，和我上一篇文章的event loop运行步骤是一模一样的

### DOM事件和event loop的总结
 - JS是单线程的
 - 异步(setTimeout, ajax等)使用回调，基于event loop
 - DOM事件也使用回调，基于event loop

DOM事件是不算异步的，只是DOM事件和异步都是基于event loop来实现的，但两者的触发时机是不一样的，并且二者的触发时机都是
浏览器来控制的


## 细谈Promise
(注意：似乎现在resolved状态变成了fulfilled状态了 但是resolve() 这个函数是存在的，没有fulfilled() 或者说resolved())
### Promise的重点
 - 三种状态
 - 状态的表现和变化
 - then和catch对状态的变化

### 三种状态
 - pending resolved rejected
 - pending --> resolved或pending --> rejected
 - 变化不可逆

```
pending 指目前状态为 在过程中，还没有结果
resolved 指解决了当前问题，已成功
rejected 指拒绝了问题，失败了
```

下面通过代码来详细讲讲这三种状态
```
执行下面代码
const p1 = new Promise((resolve, reject) => {

})
console.log('p1', p1);    
```
<img src='https://github.com/Bruce-shuai/Books/blob/main/JS基础/异步/photos/Promise%20-%201.png' height='100px'/>

从代码逻辑和图片可以得出当前Promise是处于 `pending` 状态，毕竟Promise函数内部什么内容也没有！
好，我们来看看下一段代码

```
const p2 = new Promise((resolve, reject) => {
  setTimeout(() => {
    resolve()
  })
})
console.log('p2', p2)
setTimeout(() => console.log('p2-setTimeout', p2))
```
<img src='https://github.com/Bruce-shuai/Books/blob/main/JS基础/异步/photos/Promise%20-%202.png' height='120px' />

（注意：似乎现在resolve变成了fulfilled了？！)
这里我们会看见一个比较重要的点！刚打印的时候，Promise的状态呈现的是pending，但是定时任务结束后就是fulfilled

既然展示了resolve的结果，顺便再展示一下rejected的结果

```
const p3 = new Promise((resolve, reject) => {
  setTimeout(() => {
    reject()
  })
})
console.log('p3', p3)
setTimeout(() => console.log('p3-setTimeout', p3))
```
<img src='https://github.com/Bruce-shuai/Books/blob/main/JS基础/异步/photos/Promise%20-%203.png' height='120px' />
同样，Promise开始呈现的是pending状态，定时任务结束后为rejected， 并且抛出一个错误！

### 状态的表现
 - pending状态，不会触犯then和catch
 - resolved状态，会触发后续的then回调函数    似乎现在不是resolved了，而是fulfilled了
 - rejected状态，会触发后续的catch回调函数

接下来，就用代码来展示状态的表现
```
const p1 = Promise.resolve(100)
console.log('p1', p1)
```
<img src='https://github.com/Bruce-shuai/Books/blob/main/JS基础/异步/photos/Promise%20-%204.png' height='100px' />

```
const p2 = Promise.reject('err')
console.log('p2', p2)
```
<img src='https://github.com/Bruce-shuai/Books/blob/main/JS基础/异步/photos/Promise%20-%205.png' height='80px' />

上面的代码都展示了，相应的状态以及传入的数据。
下面，我将展示resolve和rejected触发的then和catch函数

```
const p1 = Promise.resolve(100);

p1.then(data => {
  console.log('data', data);
}).catch(err => {
  console.error('err', err);
})
// 打印结果 data 100
```
可见，当Promise处于fulfilled状态的时候，then函数能够被触发，但是catch不会被触发！

```
const p2 = Promise.reject('err2');

p2.then(data2 => {
  console.log('data2', data2);
}).catch(err2 => {
  console.error('err2', err2);
})

// 打印结果 err2 err2
```
可见，当Promise处于rejected状态的时候，then函数不会被触发，但是catch会被触发

### then和catch改变状态
 - then正常返回resolved，里面有报错则返回 rejected
 - catch正常返回resolved，里面有报错则返回 rejected

```
看上面的两条结论肯定是索然无味的😴，接下来，我用代码来展示上面说的两条结论方便大家来理解
```
代码展示第一条结论
```
const p1 = Promise.resolve().then(() => {
  return 100;
})
console.log('p1', p1)   // 先pending -> 异步之后 -> fulfilled，fulfilled能够触发后续then回调
p1.then(() => {
  console.log('123')    // 123 
})

const p2 = Promise.resolve().then(() => {
  throw new Error('then error');  // 抛出错误，有报错
})
console.log('p2', p2)   // 先pending -> 异步之后 -> rejected，rejected能够触发后续catch回调
p2.then(() => {
  console.log('456')    // 什么都没有
}).catch(err => {
  console.error('error', err) // error
})
```
代码展示第二条结论
```
const p3 = Promise.reject('my error').catch(err => {
  console.error(err)
})
console.log('p3', p3) 
// 注意：  先pending -> 异步之后 -> fulfilled    
// 报错 my error

const p4 = Promise.reject('my error').catch(err => {
  throw new Error('catch err') // 跑错误，报错
})
console.log('p4', p4)
// 注意： 先pending -> 异步之后 -> rejected
// 报错 catch err

p3.then(() => {
  console.log(100)  // 100
})

p4.then(() => {
  console.log(200)  // 啥也没有
})

p4.then(() => {
  console.log(200)  
}).catch(() => {
  console.log('some err')  // some err
})

```

其实我一切想说的，就已在上面的代码中展示了，如果还有困惑，可多看多敲上面的代码
<hr />
好了，有了前面Promise的知识讲解后，我们来看看最开始的3个Promise链式调用的题。相信，应该不会难道你。

```
// 第一题
Promise.resolve().then(() => {
  console.log(1)
}).catch(() => {
  console.log(2)
}).then(() => {
  console.log(3)
})

// 打印结果： 1 3

// 第二题
Promise.resolve().then(() => {
  console.log(1) 
  throw new Error('err1')
}).catch(() => {
  console.log(2)
}).then(() => {
  console.log(3)
})

// 打印结果： 1 2 3

// 第三题
Promise.resolve().then(() => {
  console.log(1)
  throw new Error('err1')
}).catch(() => {
  console.log(2)
}).catch(() => {
  console.log(3)
})

// 打印结果： 1 2
```

